<?xml version="1.0"?> 
<robot name="door" xmlns:xacro="http://www.ros.org/wiki/xacro">

<link name="world"/>
  <joint name="fixed" type="fixed">
    <parent link="world"/>
    <child link="wall"/>
  </joint>

<link name="wall">
    <inertial>
      <mass value="100.0" />
      <inertia  ixx="1.0" ixy="0"  ixz="0"  iyy="1.0"  iyz="0"  izz="1.0" />
    </inertial>
    <visual>
      <origin xyz="0 0 1.5"/>
      <geometry>
        <box size="0.1 3 3" />
      </geometry>
    </visual>
    <collision>
      <origin xyz="0 0 1.5"/>
      <geometry>
        <box size="0.1 3 3" />
      </geometry>
    </collision>
  </link>

  <link name="door">
    <inertial>
      <mass value="1.0" />
      <inertia  ixx="1.0" ixy="0"  ixz="0"  iyy="1.0"  iyz="0"  izz="1.0" />
    </inertial>
    <visual>
      <origin xyz="0 -0.5 0"/>
      <geometry>
        <box size="0.1 1 2.8" />
      </geometry>
    </visual>
    <collision>
      <origin xyz="0 -0.5 0"/>
      <geometry>
        <box size="0.1 1 2.8" />
      </geometry>
    </collision>
  </link>

  <joint name="joint1" type="revolute">
    <limit upper="0" lower="-1.48353" velocity="0.523599" effort="200"/>
    <origin xyz="0 -1.5 1.5" rpy="0 0 0"/>
    <axis xyz="0 0 1" />
    <parent link="wall"/>
    <child link="door"/>
  </joint>   

  <gazebo reference="wall">
    <material>Gazebo/Bricks</material>
    <static>1</static>
  </gazebo>

  <gazebo reference="door">
    <material>Gazebo/Wood</material>
    <mu1>1.0</mu1>
    <mu2>1.0</mu2>
    <static>0</static>
  </gazebo>

<!--................. Gazebo plugins....................-->
  <gazebo>
	<plugin name="gazebo_ros_control" filename="libgazebo_ros_control.so">
	    <robotNamespace>/ram</robotNamespace>
	</plugin>
  </gazebo>
</robot>
